Workbook
Name Player_List: Archetype_Scores!$A$1:$A$50

Sheet Raw_Data
A1: Player | B1: Squad | C1: Age | D1: Minutes | E1: Shots_90 | F1: xG_90 | G1: npxG_90 | H1: Touches_Box_90 | I1: Shots_per_Touch | J1: Aerials_Won_Pct | K1: Aerials_Won_90 | L1: Fouls_Drawn_90 | M1: SoT_Pct | N1: Avg_Shot_Distance | O1: G_minus_xG | P1: Passes_Received_90 | Q1: Key_Passes_90 | R1: Prog_Passes_Received_90 | S1: Prog_Carries_90 | T1: Carry_Distance_90 | U1: Carries_Into_Box_90
A2: Elijah Adebayo | B2: Luton Town | C2: 25 | D2: 1419 | E2: 1.97 | F2: 0.37 | G2: 0.37 | H2: 5.19 | I2: =E2/H2 -> 0.37957611 | J2: 50 | K2: 2.72 | L2: 1.01 | M2: 45.2 | N2: 9.6 | O2: 4.1 | P2: 21.3 | Q2: 14 | R2: 110 | S2: 1.01 | T2: 26.9 | U2: 13
A3: Simon Adingra | B3: Brighton | C3: 21 | D3: 2222 | E3: 2.11 | F3: 0.17 | G3: 0.17 | H3: 6.19 | I3: =E3/H3 -> 0.34087237 | J3: 40 | K3: 0.32 | L3: 0.77 | M3: 42.3 | N3: 15.9 | O3: 1.7 | P3: 32.2 | Q3: 33 | R3: 278 | S3: 4.49 | T3: 121.3 | U3: 63
A4: Miguel Almirón | B4: Newcastle Utd | C4: 29 | D4: 1937 | E4: 1.91 | F4: 0.21 | G4: 0.21 | H4: 4 | I4: =E4/H4 -> 0.4775 | J4: 46.2 | K4: 0.28 | L4: 1.02 | M4: 29.3 | N4: 16.1 | O4: -1.5 | P4: 34.5 | Q4: 24 | R4: 162 | S4: 3.63 | T4: 105.9 | U4: 22
A5: Zeki Amdouni | B5: Burnley | C5: 22 | D5: 1953 | E5: 2.21 | F5: 0.27 | G5: 0.23 | H5: 3.13 | I5: =E5/H5 -> 0.70607029 | J5: 21.1 | K5: 0.69 | L5: 1.8 | M5: 43.8 | N5: 17.8 | O5: -0.8 | P5: 23.6 | Q5: 16 | R5: 93 | S5: 2.9 | T5: 76.2 | U5: 20
A6: Michail Antonio | B6: West Ham | C6: 33 | D6: 1695 | E6: 1.59 | F6: 0.31 | G6: 0.31 | H6: 3.14 | I6: =E6/H6 -> 0.50636943 | J6: 38.4 | K6: 1.76 | L6: 1.49 | M6: 46.7 | N6: 13.1 | O6: 0.2 | P6: 21.2 | Q6: 8 | R6: 104 | S6: 2.55 | T6: 57.7 | U6: 19
A7: Antony | B7: Manchester Utd | C7: 23 | D7: 1324 | E7: 2.92 | F7: 0.23 | G7: 0.23 | H7: 3.95 | I7: =E7/H7 -> 0.73924051 | J7: 8.7 | K7: 0.14 | L7: 2.18 | M7: 34.9 | N7: 18.9 | O7: -2.4 | P7: 38.8 | Q7: 22 | R7: 149 | S7: 3.61 | T7: 132.9 | U7: 23
A8: Taiwo Awoniyi | B8: Nott'ham Forest | C8: 25 | D8: 1042 | E8: 1.9 | F8: 0.41 | G8: 0.41 | H8: 3.71 | I8: =E8/H8 -> 0.51212938 | J8: 30.4 | K8: 1.81 | L8: 1.38 | M8: 50 | N8: 11.5 | O8: 1.3 | P8: 18 | Q8: 10 | R8: 45 | S8: 0.69 | T8: 27.6 | U8: 6
A9: Beto | B9: Everton | C9: 25 | D9: 951 | E9: 3.97 | F9: 0.64 | G9: 0.57 | H9: 6.04 | I9: =E9/H9 -> 0.65728477 | J9: 45.6 | K9: 4.43 | L9: 1.79 | M9: 28.6 | N9: 14.7 | O9: -3.8 | P9: 23.6 | Q9: 11 | R9: 58 | S9: 1.32 | T9: 36.2 | U9: 13
A10: Jarrod Bowen | B10: West Ham | C10: 26 | D10: 3019 | E10: 2.5 | F10: 0.35 | G10: 0.35 | H10: 5.19 | I10: =E10/H10 -> 0.48169557 | J10: 32 | K10: 0.99 | L10: 1.25 | M10: 44 | N10: 14.2 | O10: 4.4 | P10: 22.2 | Q10: 31 | R10: 186 | S10: 2.69 | T10: 63.9 | U10: 49
A11: Dominic Calvert-Lewin | B11: Everton | C11: 26 | D11: 2171 | E11: 2.94 | F11: 0.54 | G11: 0.47 | H11: 5.15 | I11: =E11/H11 -> 0.57087379 | J11: 48.8 | K11: 5.68 | L11: 1.33 | M11: 39.4 | N11: 13.9 | O11: -5.9 | P11: 23.4 | Q11: 19 | R11: 122 | S11: 1.49 | T11: 32.9 | U11: 22
A12: Bobby De Cordova-Reid | B12: Fulham | C12: 30 | D12: 1423 | E12: 2.09 | F12: 0.29 | G12: 0.28 | H12: 3.48 | I12: =E12/H12 -> 0.60057471 | J12: 35.1 | K12: 0.82 | L12: 1.58 | M12: 24.2 | N12: 15.7 | O12: 1.4 | P12: 30.1 | Q12: 17 | R12: 95 | S12: 2.22 | T12: 57 | U12: 11
A13: Luis Díaz | B13: Liverpool | C13: 26 | D13: 2629 | E13: 3.22 | F13: 0.41 | G13: 0.41 | H13: 7.5 | I13: =E13/H13 -> 0.42933333 | J13: 35.1 | K13: 0.89 | L13: 1.44 | M13: 34 | N13: 15 | O13: -3.9 | P13: 38.6 | Q13: 64 | R13: 302 | S13: 4.69 | T13: 126.4 | U13: 70
... A50: Chris Wood | B50: Nott'ham Forest | C50: 31 | D50: 1812 | E50: 2.38 | F50: 0.59 | G50: 0.59 | H50: 4.58 | I50: =E50/H50 -> 0.51965066 | J50: 42.6 | K50: 3.58 | L50: 0.65 | M50: 54.2 | N50: 10.2 | O50: 2.1 | P50: 23.3 | Q50: 22 | R50: 76 | S50: 0.8 | T50: 23.7 | U50: 7

Sheet Normalized
A1: Player | B1: Squad | C1: Age | D1: Minutes | E1: Shots_90 | F1: xG_90 | G1: npxG_90 | H1: Touches_Box_90 | I1: Shots_per_Touch | J1: Aerials_Won_Pct | K1: Aerials_Won_90 | L1: Fouls_Drawn_90 | M1: SoT_Pct | N1: Avg_Shot_Distance | O1: G_minus_xG | P1: Passes_Received_90 | Q1: Key_Passes_90 | R1: Prog_Passes_Received_90 | S1: Prog_Carries_90 | T1: Carry_Distance_90 | U1: Carries_Into_Box_90
A2: =Raw_Data!A2 -> Elijah Adebayo | B2: =Raw_Data!B2 -> Luton Town | C2: =Raw_Data!C2 -> 25 | D2: =Raw_Data!D2 -> 1419 | E2: =_xlfn.PERCENTRANK.INC(Raw_Data!$E$2:$E$60, Raw_Data!E2) -> 0.125 | F2: =_xlfn.PERCENTRANK.INC(Raw_Data!$F$2:$F$60, Raw_Data!F2) -> 0.437 | G2: =_xlfn.PERCENTRANK.INC(Raw_Data!$G$2:$G$60, Raw_Data!G2) -> 0.5 | H2: =_xlfn.PERCENTRANK.INC(Raw_Data!$H$2:$H$60, Raw_Data!H2) -> 0.479 | I2: =_xlfn.PERCENTRANK.INC(Raw_Data!$I$2:$I$60, Raw_Data!I2) -> 0.104 | J2: =_xlfn.PERCENTRANK.INC(Raw_Data!$J$2:$J$60, Raw_Data!J2) -> 0.979 | K2: =_xlfn.PERCENTRANK.INC(Raw_Data!$K$2:$K$60, Raw_Data!K2) -> 0.854 | L2: =_xlfn.PERCENTRANK.INC(Raw_Data!$L$2:$L$60, Raw_Data!L2) -> 0.166 | M2: =_xlfn.PERCENTRANK.INC(Raw_Data!$M$2:$M$60, Raw_Data!M2) -> 0.75 | N2: =Raw_Data!N2 -> 9.6 | O2: =Raw_Data!O2 -> 4.1 | P2: =_xlfn.PERCENTRANK.INC(Raw_Data!$P$2:$P$60, Raw_Data!P2) -> 0.187 | Q2: =_xlfn.PERCENTRANK.INC(Raw_Data!$Q$2:$Q$60, Raw_Data!Q2) -> 0.187 | R2: =_xlfn.PERCENTRANK.INC(Raw_Data!$R$2:$R$60, Raw_Data!R2) -> 0.312 | S2: =_xlfn.PERCENTRANK.INC(Raw_Data!$S$2:$S$60, Raw_Data!S2) -> 0.145 | T2: =_xlfn.PERCENTRANK.INC(Raw_Data!$T$2:$T$60, Raw_Data!T2) -> 0.083 | U2: =_xlfn.PERCENTRANK.INC(Raw_Data!$U$2:$U$60, Raw_Data!U2) -> 0.187
A3: =Raw_Data!A3 -> Simon Adingra | B3: =Raw_Data!B3 -> Brighton | C3: =Raw_Data!C3 -> 21 | D3: =Raw_Data!D3 -> 2222 | E3: =_xlfn.PERCENTRANK.INC(Raw_Data!$E$2:$E$60, Raw_Data!E3) -> 0.208 | F3: =_xlfn.PERCENTRANK.INC(Raw_Data!$F$2:$F$60, Raw_Data!F3) -> 0 | G3: =_xlfn.PERCENTRANK.INC(Raw_Data!$G$2:$G$60, Raw_Data!G3) -> 0.041 | H3: =_xlfn.PERCENTRANK.INC(Raw_Data!$H$2:$H$60, Raw_Data!H3) -> 0.645 | I3: =_xlfn.PERCENTRANK.INC(Raw_Data!$I$2:$I$60, Raw_Data!I3) -> 0.062 | J3: =_xlfn.PERCENTRANK.INC(Raw_Data!$J$2:$J$60, Raw_Data!J3) -> 0.625 | K3: =_xlfn.PERCENTRANK.INC(Raw_Data!$K$2:$K$60, Raw_Data!K3) -> 0.166 | L3: =_xlfn.PERCENTRANK.INC(Raw_Data!$L$2:$L$60, Raw_Data!L3) -> 0.062 | M3: =_xlfn.PERCENTRANK.INC(Raw_Data!$M$2:$M$60, Raw_Data!M3) -> 0.562 | N3: =Raw_Data!N3 -> 15.9 | O3: =Raw_Data!O3 -> 1.7 | P3: =_xlfn.PERCENTRANK.INC(Raw_Data!$P$2:$P$60, Raw_Data!P3) -> 0.625 | Q3: =_xlfn.PERCENTRANK.INC(Raw_Data!$Q$2:$Q$60, Raw_Data!Q3) -> 0.708 | R3: =_xlfn.PERCENTRANK.INC(Raw_Data!$R$2:$R$60, Raw_Data!R3) -> 0.854 | S3: =_xlfn.PERCENTRANK.INC(Raw_Data!$S$2:$S$60, Raw_Data!S3) -> 0.854 | T3: =_xlfn.PERCENTRANK.INC(Raw_Data!$T$2:$T$60, Raw_Data!T3) -> 0.833 | U3: =_xlfn.PERCENTRANK.INC(Raw_Data!$U$2:$U$60, Raw_Data!U3) -> 0.854
A4: =Raw_Data!A4 -> Miguel Almirón | B4: =Raw_Data!B4 -> Newcastle Utd | C4: =Raw_Data!C4 -> 29 | D4: =Raw_Data!D4 -> 1937 | E4: =_xlfn.PERCENTRANK.INC(Raw_Data!$E$2:$E$60, Raw_Data!E4) -> 0.104 | F4: =_xlfn.PERCENTRANK.INC(Raw_Data!$F$2:$F$60, Raw_Data!F4) -> 0.083 | G4: =_xlfn.PERCENTRANK.INC(Raw_Data!$G$2:$G$60, Raw_Data!G4) -> 0.125 | H4: =_xlfn.PERCENTRANK.INC(Raw_Data!$H$2:$H$60, Raw_Data!H4) -> 0.166 | I4: =_xlfn.PERCENTRANK.INC(Raw_Data!$I$2:$I$60, Raw_Data!I4) -> 0.416 | J4: =_xlfn.PERCENTRANK.INC(Raw_Data!$J$2:$J$60, Raw_Data!J4) -> 0.875 | K4: =_xlfn.PERCENTRANK.INC(Raw_Data!$K$2:$K$60, Raw_Data!K4) -> 0.104 | L4: =_xlfn.PERCENTRANK.INC(Raw_Data!$L$2:$L$60, Raw_Data!L4) -> 0.187 | M4: =_xlfn.PERCENTRANK.INC(Raw_Data!$M$2:$M$60, Raw_Data!M4) -> 0.062 | N4: =Raw_Data!N4 -> 16.1 | O4: =Raw_Data!O4 -> -1.5 | P4: =_xlfn.PERCENTRANK.INC(Raw_Data!$P$2:$P$60, Raw_Data!P4) -> 0.791 | Q4: =_xlfn.PERCENTRANK.INC(Raw_Data!$Q$2:$Q$60, Raw_Data!Q4) -> 0.458 | R4: =_xlfn.PERCENTRANK.INC(Raw_Data!$R$2:$R$60, Raw_Data!R4) -> 0.583 | S4: =_xlfn.PERCENTRANK.INC(Raw_Data!$S$2:$S$60, Raw_Data!S4) -> 0.687 | T4: =_xlfn.PERCENTRANK.INC(Raw_Data!$T$2:$T$60, Raw_Data!T4) -> 0.75 | U4: =_xlfn.PERCENTRANK.INC(Raw_Data!$U$2:$U$60, Raw_Data!U4) -> 0.416
A5: =Raw_Data!A5 -> Zeki Amdouni | B5: =Raw_Data!B5 -> Burnley | C5: =Raw_Data!C5 -> 22 | D5: =Raw_Data!D5 -> 1953 | E5: =_xlfn.PERCENTRANK.INC(Raw_Data!$E$2:$E$60, Raw_Data!E5) -> 0.291 | F5: =_xlfn.PERCENTRANK.INC(Raw_Data!$F$2:$F$60, Raw_Data!F5) -> 0.208 | G5: =_xlfn.PERCENTRANK.INC(Raw_Data!$G$2:$G$60, Raw_Data!G5) -> 0.166 | H5: =_xlfn.PERCENTRANK.INC(Raw_Data!$H$2:$H$60, Raw_Data!H5) -> 0.041 | I5: =_xlfn.PERCENTRANK.INC(Raw_Data!$I$2:$I$60, Raw_Data!I5) -> 0.916 | J5: =_xlfn.PERCENTRANK.INC(Raw_Data!$J$2:$J$60, Raw_Data!J5) -> 0.062 | K5: =_xlfn.PERCENTRANK.INC(Raw_Data!$K$2:$K$60, Raw_Data!K5) -> 0.354 | L5: =_xlfn.PERCENTRANK.INC(Raw_Data!$L$2:$L$60, Raw_Data!L5) -> 0.729 | M5: =_xlfn.PERCENTRANK.INC(Raw_Data!$M$2:$M$60, Raw_Data!M5) -> 0.625 | N5: =Raw_Data!N5 -> 17.8 | O5: =Raw_Data!O5 -> -0.8 | P5: =_xlfn.PERCENTRANK.INC(Raw_Data!$P$2:$P$60, Raw_Data!P5) -> 0.354 | Q5: =_xlfn.PERCENTRANK.INC(Raw_Data!$Q$2:$Q$60, Raw_Data!Q5) -> 0.25 | R5: =_xlfn.PERCENTRANK.INC(Raw_Data!$R$2:$R$60, Raw_Data!R5) -> 0.208 | S5: =_xlfn.PERCENTRANK.INC(Raw_Data!$S$2:$S$60, Raw_Data!S5) -> 0.583 | T5: =_xlfn.PERCENTRANK.INC(Raw_Data!$T$2:$T$60, Raw_Data!T5) -> 0.562 | U5: =_xlfn.PERCENTRANK.INC(Raw_Data!$U$2:$U$60, Raw_Data!U5) -> 0.375
A6: =Raw_Data!A6 -> Michail Antonio | B6: =Raw_Data!B6 -> West Ham | C6: =Raw_Data!C6 -> 33 | D6: =Raw_Data!D6 -> 1695 | E6: =_xlfn.PERCENTRANK.INC(Raw_Data!$E$2:$E$60, Raw_Data!E6) -> 0.02 | F6: =_xlfn.PERCENTRANK.INC(Raw_Data!$F$2:$F$60, Raw_Data!F6) -> 0.333 | G6: =_xlfn.PERCENTRANK.INC(Raw_Data!$G$2:$G$60, Raw_Data!G6) -> 0.333 | H6: =_xlfn.PERCENTRANK.INC(Raw_Data!$H$2:$H$60, Raw_Data!H6) -> 0.062 | I6: =_xlfn.PERCENTRANK.INC(Raw_Data!$I$2:$I$60, Raw_Data!I6) -> 0.52 | J6: =_xlfn.PERCENTRANK.INC(Raw_Data!$J$2:$J$60, Raw_Data!J6) -> 0.562 | K6: =_xlfn.PERCENTRANK.INC(Raw_Data!$K$2:$K$60, Raw_Data!K6) -> 0.729 | L6: =_xlfn.PERCENTRANK.INC(Raw_Data!$L$2:$L$60, Raw_Data!L6) -> 0.541 | M6: =_xlfn.PERCENTRANK.INC(Raw_Data!$M$2:$M$60, Raw_Data!M6) -> 0.812 | N6: =Raw_Data!N6 -> 13.1 | O6: =Raw_Data!O6 -> 0.2 | P6: =_xlfn.PERCENTRANK.INC(Raw_Data!$P$2:$P$60, Raw_Data!P6) -> 0.145 | Q6: =_xlfn.PERCENTRANK.INC(Raw_Data!$Q$2:$Q$60, Raw_Data!Q6) -> 0.02 | R6: =_xlfn.PERCENTRANK.INC(Raw_Data!$R$2:$R$60, Raw_Data!R6) -> 0.27 | S6: =_xlfn.PERCENTRANK.INC(Raw_Data!$S$2:$S$60, Raw_Data!S6) -> 0.5 | T6: =_xlfn.PERCENTRANK.INC(Raw_Data!$T$2:$T$60, Raw_Data!T6) -> 0.458 | U6: =_xlfn.PERCENTRANK.INC(Raw_Data!$U$2:$U$60, Raw_Data!U6) -> 0.354
A7: =Raw_Data!A7 -> Antony | B7: =Raw_Data!B7 -> Manchester Utd | C7: =Raw_Data!C7 -> 23 | D7: =Raw_Data!D7 -> 1324 | E7: =_xlfn.PERCENTRANK.INC(Raw_Data!$E$2:$E$60, Raw_Data!E7) -> 0.645 | F7: =_xlfn.PERCENTRANK.INC(Raw_Data!$F$2:$F$60, Raw_Data!F7) -> 0.166 | G7: =_xlfn.PERCENTRANK.INC(Raw_Data!$G$2:$G$60, Raw_Data!G7) -> 0.166 | H7: =_xlfn.PERCENTRANK.INC(Raw_Data!$H$2:$H$60, Raw_Data!H7) -> 0.145 | I7: =_xlfn.PERCENTRANK.INC(Raw_Data!$I$2:$I$60, Raw_Data!I7) -> 0.958 | J7: =_xlfn.PERCENTRANK.INC(Raw_Data!$J$2:$J$60, Raw_Data!J7) -> 0 | K7: =_xlfn.PERCENTRANK.INC(Raw_Data!$K$2:$K$60, Raw_Data!K7) -> 0 | L7: =_xlfn.PERCENTRANK.INC(Raw_Data!$L$2:$L$60, Raw_Data!L7) -> 0.958 | M7: =_xlfn.PERCENTRANK.INC(Raw_Data!$M$2:$M$60, Raw_Data!M7) -> 0.312 | N7: =Raw_Data!N7 -> 18.9 | O7: =Raw_Data!O7 -> -2.4 | P7: =_xlfn.PERCENTRANK.INC(Raw_Data!$P$2:$P$60, Raw_Data!P7) -> 0.875 | Q7: =_xlfn.PERCENTRANK.INC(Raw_Data!$Q$2:$Q$60, Raw_Data!Q7) -> 0.354 | R7: =_xlfn.PERCENTRANK.INC(Raw_Data!$R$2:$R$60, Raw_Data!R7) -> 0.52 | S7: =_xlfn.PERCENTRANK.INC(Raw_Data!$S$2:$S$60, Raw_Data!S7) -> 0.666 | T7: =_xlfn.PERCENTRANK.INC(Raw_Data!$T$2:$T$60, Raw_Data!T7) -> 0.895 | U7: =_xlfn.PERCENTRANK.INC(Raw_Data!$U$2:$U$60, Raw_Data!U7) -> 0.479
A8: =Raw_Data!A8 -> Taiwo Awoniyi | B8: =Raw_Data!B8 -> Nott'ham Forest | C8: =Raw_Data!C8 -> 25 | D8: =Raw_Data!D8 -> 1042 | E8: =_xlfn.PERCENTRANK.INC(Raw_Data!$E$2:$E$60, Raw_Data!E8) -> 0.083 | F8: =_xlfn.PERCENTRANK.INC(Raw_Data!$F$2:$F$60, Raw_Data!F8) -> 0.583 | G8: =_xlfn.PERCENTRANK.INC(Raw_Data!$G$2:$G$60, Raw_Data!G8) -> 0.666 | H8: =_xlfn.PERCENTRANK.INC(Raw_Data!$H$2:$H$60, Raw_Data!H8) -> 0.125 | I8: =_xlfn.PERCENTRANK.INC(Raw_Data!$I$2:$I$60, Raw_Data!I8) -> 0.541 | J8: =_xlfn.PERCENTRANK.INC(Raw_Data!$J$2:$J$60, Raw_Data!J8) -> 0.229 | K8: =_xlfn.PERCENTRANK.INC(Raw_Data!$K$2:$K$60, Raw_Data!K8) -> 0.75 | L8: =_xlfn.PERCENTRANK.INC(Raw_Data!$L$2:$L$60, Raw_Data!L8) -> 0.479 | M8: =_xlfn.PERCENTRANK.INC(Raw_Data!$M$2:$M$60, Raw_Data!M8) -> 0.875 | N8: =Raw_Data!N8 -> 11.5 | O8: =Raw_Data!O8 -> 1.3 | P8: =_xlfn.PERCENTRANK.INC(Raw_Data!$P$2:$P$60, Raw_Data!P8) -> 0.062 | Q8: =_xlfn.PERCENTRANK.INC(Raw_Data!$Q$2:$Q$60, Raw_Data!Q8) -> 0.083 | R8: =_xlfn.PERCENTRANK.INC(Raw_Data!$R$2:$R$60, Raw_Data!R8) -> 0 | S8: =_xlfn.PERCENTRANK.INC(Raw_Data!$S$2:$S$60, Raw_Data!S8) -> 0.041 | T8: =_xlfn.PERCENTRANK.INC(Raw_Data!$T$2:$T$60, Raw_Data!T8) -> 0.125 | U8: =_xlfn.PERCENTRANK.INC(Raw_Data!$U$2:$U$60, Raw_Data!U8) -> 0.083
A9: =Raw_Data!A9 -> Beto | B9: =Raw_Data!B9 -> Everton | C9: =Raw_Data!C9 -> 25 | D9: =Raw_Data!D9 -> 951 | E9: =_xlfn.PERCENTRANK.INC(Raw_Data!$E$2:$E$60, Raw_Data!E9) -> 0.937 | F9: =_xlfn.PERCENTRANK.INC(Raw_Data!$F$2:$F$60, Raw_Data!F9) -> 0.895 | G9: =_xlfn.PERCENTRANK.INC(Raw_Data!$G$2:$G$60, Raw_Data!G9) -> 0.854 | H9: =_xlfn.PERCENTRANK.INC(Raw_Data!$H$2:$H$60, Raw_Data!H9) -> 0.625 | I9: =_xlfn.PERCENTRANK.INC(Raw_Data!$I$2:$I$60, Raw_Data!I9) -> 0.895 | J9: =_xlfn.PERCENTRANK.INC(Raw_Data!$J$2:$J$60, Raw_Data!J9) -> 0.833 | K9: =_xlfn.PERCENTRANK.INC(Raw_Data!$K$2:$K$60, Raw_Data!K9) -> 0.958 | L9: =_xlfn.PERCENTRANK.INC(Raw_Data!$L$2:$L$60, Raw_Data!L9) -> 0.708 | M9: =_xlfn.PERCENTRANK.INC(Raw_Data!$M$2:$M$60, Raw_Data!M9) -> 0.041 | N9: =Raw_Data!N9 -> 14.7 | O9: =Raw_Data!O9 -> -3.8 | P9: =_xlfn.PERCENTRANK.INC(Raw_Data!$P$2:$P$60, Raw_Data!P9) -> 0.354 | Q9: =_xlfn.PERCENTRANK.INC(Raw_Data!$Q$2:$Q$60, Raw_Data!Q9) -> 0.104 | R9: =_xlfn.PERCENTRANK.INC(Raw_Data!$R$2:$R$60, Raw_Data!R9) -> 0.02 | S9: =_xlfn.PERCENTRANK.INC(Raw_Data!$S$2:$S$60, Raw_Data!S9) -> 0.208 | T9: =_xlfn.PERCENTRANK.INC(Raw_Data!$T$2:$T$60, Raw_Data!T9) -> 0.229 | U9: =_xlfn.PERCENTRANK.INC(Raw_Data!$U$2:$U$60, Raw_Data!U9) -> 0.187
A10: =Raw_Data!A10 -> Jarrod Bowen | B10: =Raw_Data!B10 -> West Ham | C10: =Raw_Data!C10 -> 26 | D10: =Raw_Data!D10 -> 3019 | E10: =_xlfn.PERCENTRANK.INC(Raw_Data!$E$2:$E$60, Raw_Data!E10) -> 0.458 | F10: =_xlfn.PERCENTRANK.INC(Raw_Data!$F$2:$F$60, Raw_Data!F10) -> 0.416 | G10: =_xlfn.PERCENTRANK.INC(Raw_Data!$G$2:$G$60, Raw_Data!G10) -> 0.479 | H10: =_xlfn.PERCENTRANK.INC(Raw_Data!$H$2:$H$60, Raw_Data!H10) -> 0.479 | I10: =_xlfn.PERCENTRANK.INC(Raw_Data!$I$2:$I$60, Raw_Data!I10) -> 0.437 | J10: =_xlfn.PERCENTRANK.INC(Raw_Data!$J$2:$J$60, Raw_Data!J10) -> 0.291 | K10: =_xlfn.PERCENTRANK.INC(Raw_Data!$K$2:$K$60, Raw_Data!K10) -> 0.52 | L10: =_xlfn.PERCENTRANK.INC(Raw_Data!$L$2:$L$60, Raw_Data!L10) -> 0.333 | M10: =_xlfn.PERCENTRANK.INC(Raw_Data!$M$2:$M$60, Raw_Data!M10) -> 0.687 | N10: =Raw_Data!N10 -> 14.2 | O10: =Raw_Data!O10 -> 4.4 | P10: =_xlfn.PERCENTRANK.INC(Raw_Data!$P$2:$P$60, Raw_Data!P10) -> 0.25 | Q10: =_xlfn.PERCENTRANK.INC(Raw_Data!$Q$2:$Q$60, Raw_Data!Q10) -> 0.625 | R10: =_xlfn.PERCENTRANK.INC(Raw_Data!$R$2:$R$60, Raw_Data!R10) -> 0.687 | S10: =_xlfn.PERCENTRANK.INC(Raw_Data!$S$2:$S$60, Raw_Data!S10) -> 0.541 | T10: =_xlfn.PERCENTRANK.INC(Raw_Data!$T$2:$T$60, Raw_Data!T10) -> 0.479 | U10: =_xlfn.PERCENTRANK.INC(Raw_Data!$U$2:$U$60, Raw_Data!U10) -> 0.791
A11: =Raw_Data!A11 -> Dominic Calvert-Lewin | B11: =Raw_Data!B11 -> Everton | C11: =Raw_Data!C11 -> 26 | D11: =Raw_Data!D11 -> 2171 | E11: =_xlfn.PERCENTRANK.INC(Raw_Data!$E$2:$E$60, Raw_Data!E11) -> 0.666 | F11: =_xlfn.PERCENTRANK.INC(Raw_Data!$F$2:$F$60, Raw_Data!F11) -> 0.812 | G11: =_xlfn.PERCENTRANK.INC(Raw_Data!$G$2:$G$60, Raw_Data!G11) -> 0.75 | H11: =_xlfn.PERCENTRANK.INC(Raw_Data!$H$2:$H$60, Raw_Data!H11) -> 0.437 | I11: =_xlfn.PERCENTRANK.INC(Raw_Data!$I$2:$I$60, Raw_Data!I11) -> 0.77 | J11: =_xlfn.PERCENTRANK.INC(Raw_Data!$J$2:$J$60, Raw_Data!J11) -> 0.937 | K11: =_xlfn.PERCENTRANK.INC(Raw_Data!$K$2:$K$60, Raw_Data!K11) -> 0.979 | L11: =_xlfn.PERCENTRANK.INC(Raw_Data!$L$2:$L$60, Raw_Data!L11) -> 0.437 | M11: =_xlfn.PERCENTRANK.INC(Raw_Data!$M$2:$M$60, Raw_Data!M11) -> 0.479 | N11: =Raw_Data!N11 -> 13.9 | O11: =Raw_Data!O11 -> -5.9 | P11: =_xlfn.PERCENTRANK.INC(Raw_Data!$P$2:$P$60, Raw_Data!P11) -> 0.333 | Q11: =_xlfn.PERCENTRANK.INC(Raw_Data!$Q$2:$Q$60, Raw_Data!Q11) -> 0.312 | R11: =_xlfn.PERCENTRANK.INC(Raw_Data!$R$2:$R$60, Raw_Data!R11) -> 0.375 | S11: =_xlfn.PERCENTRANK.INC(Raw_Data!$S$2:$S$60, Raw_Data!S11) -> 0.312 | T11: =_xlfn.PERCENTRANK.INC(Raw_Data!$T$2:$T$60, Raw_Data!T11) -> 0.208 | U11: =_xlfn.PERCENTRANK.INC(Raw_Data!$U$2:$U$60, Raw_Data!U11) -> 0.416
A12: =Raw_Data!A12 -> Bobby De Cordova-Reid | B12: =Raw_Data!B12 -> Fulham | C12: =Raw_Data!C12 -> 30 | D12: =Raw_Data!D12 -> 1423 | E12: =_xlfn.PERCENTRANK.INC(Raw_Data!$E$2:$E$60, Raw_Data!E12) -> 0.187 | F12: =_xlfn.PERCENTRANK.INC(Raw_Data!$F$2:$F$60, Raw_Data!F12) -> 0.229 | G12: =_xlfn.PERCENTRANK.INC(Raw_Data!$G$2:$G$60, Raw_Data!G12) -> 0.25 | H12: =_xlfn.PERCENTRANK.INC(Raw_Data!$H$2:$H$60, Raw_Data!H12) -> 0.104 | I12: =_xlfn.PERCENTRANK.INC(Raw_Data!$I$2:$I$60, Raw_Data!I12) -> 0.812 | J12: =_xlfn.PERCENTRANK.INC(Raw_Data!$J$2:$J$60, Raw_Data!J12) -> 0.375 | K12: =_xlfn.PERCENTRANK.INC(Raw_Data!$K$2:$K$60, Raw_Data!K12) -> 0.395 | L12: =_xlfn.PERCENTRANK.INC(Raw_Data!$L$2:$L$60, Raw_Data!L12) -> 0.604 | M12: =_xlfn.PERCENTRANK.INC(Raw_Data!$M$2:$M$60, Raw_Data!M12) -> 0 | N12: =Raw_Data!N12 -> 15.7 | O12: =Raw_Data!O12 -> 1.4 | P12: =_xlfn.PERCENTRANK.INC(Raw_Data!$P$2:$P$60, Raw_Data!P12) -> 0.562 | Q12: =_xlfn.PERCENTRANK.INC(Raw_Data!$Q$2:$Q$60, Raw_Data!Q12) -> 0.27 | R12: =_xlfn.PERCENTRANK.INC(Raw_Data!$R$2:$R$60, Raw_Data!R12) -> 0.229 | S12: =_xlfn.PERCENTRANK.INC(Raw_Data!$S$2:$S$60, Raw_Data!S12) -> 0.416 | T12: =_xlfn.PERCENTRANK.INC(Raw_Data!$T$2:$T$60, Raw_Data!T12) -> 0.437 | U12: =_xlfn.PERCENTRANK.INC(Raw_Data!$U$2:$U$60, Raw_Data!U12) -> 0.125
A13: =Raw_Data!A13 -> Luis Díaz | B13: =Raw_Data!B13 -> Liverpool | C13: =Raw_Data!C13 -> 26 | D13: =Raw_Data!D13 -> 2629 | E13: =_xlfn.PERCENTRANK.INC(Raw_Data!$E$2:$E$60, Raw_Data!E13) -> 0.812 | F13: =_xlfn.PERCENTRANK.INC(Raw_Data!$F$2:$F$60, Raw_Data!F13) -> 0.583 | G13: =_xlfn.PERCENTRANK.INC(Raw_Data!$G$2:$G$60, Raw_Data!G13) -> 0.666 | H13: =_xlfn.PERCENTRANK.INC(Raw_Data!$H$2:$H$60, Raw_Data!H13) -> 0.833 | I13: =_xlfn.PERCENTRANK.INC(Raw_Data!$I$2:$I$60, Raw_Data!I13) -> 0.291 | J13: =_xlfn.PERCENTRANK.INC(Raw_Data!$J$2:$J$60, Raw_Data!J13) -> 0.375 | K13: =_xlfn.PERCENTRANK.INC(Raw_Data!$K$2:$K$60, Raw_Data!K13) -> 0.458 | L13: =_xlfn.PERCENTRANK.INC(Raw_Data!$L$2:$L$60, Raw_Data!L13) -> 0.52 | M13: =_xlfn.PERCENTRANK.INC(Raw_Data!$M$2:$M$60, Raw_Data!M13) -> 0.229 | N13: =Raw_Data!N13 -> 15 | O13: =Raw_Data!O13 -> -3.9 | P13: =_xlfn.PERCENTRANK.INC(Raw_Data!$P$2:$P$60, Raw_Data!P13) -> 0.854 | Q13: =_xlfn.PERCENTRANK.INC(Raw_Data!$Q$2:$Q$60, Raw_Data!Q13) -> 0.937 | R13: =_xlfn.PERCENTRANK.INC(Raw_Data!$R$2:$R$60, Raw_Data!R13) -> 0.916 | S13: =_xlfn.PERCENTRANK.INC(Raw_Data!$S$2:$S$60, Raw_Data!S13) -> 0.875 | T13: =_xlfn.PERCENTRANK.INC(Raw_Data!$T$2:$T$60, Raw_Data!T13) -> 0.854 | U13: =_xlfn.PERCENTRANK.INC(Raw_Data!$U$2:$U$60, Raw_Data!U13) -> 0.937
... A50: =Raw_Data!A50 -> Chris Wood | B50: =Raw_Data!B50 -> Nott'ham Forest | C50: =Raw_Data!C50 -> 31 | D50: =Raw_Data!D50 -> 1812 | E50: =_xlfn.PERCENTRANK.INC(Raw_Data!$E$2:$E$60, Raw_Data!E50) -> 0.375 | F50: =_xlfn.PERCENTRANK.INC(Raw_Data!$F$2:$F$60, Raw_Data!F50) -> 0.854 | G50: =_xlfn.PERCENTRANK.INC(Raw_Data!$G$2:$G$60, Raw_Data!G50) -> 0.895 | H50: =_xlfn.PERCENTRANK.INC(Raw_Data!$H$2:$H$60, Raw_Data!H50) -> 0.333 | I50: =_xlfn.PERCENTRANK.INC(Raw_Data!$I$2:$I$60, Raw_Data!I50) -> 0.604 | J50: =_xlfn.PERCENTRANK.INC(Raw_Data!$J$2:$J$60, Raw_Data!J50) -> 0.75 | K50: =_xlfn.PERCENTRANK.INC(Raw_Data!$K$2:$K$60, Raw_Data!K50) -> 0.916 | L50: =_xlfn.PERCENTRANK.INC(Raw_Data!$L$2:$L$60, Raw_Data!L50) -> 0.02 | M50: =_xlfn.PERCENTRANK.INC(Raw_Data!$M$2:$M$60, Raw_Data!M50) -> 0.937 | N50: =Raw_Data!N50 -> 10.2 | O50: =Raw_Data!O50 -> 2.1 | P50: =_xlfn.PERCENTRANK.INC(Raw_Data!$P$2:$P$60, Raw_Data!P50) -> 0.312 | Q50: =_xlfn.PERCENTRANK.INC(Raw_Data!$Q$2:$Q$60, Raw_Data!Q50) -> 0.354 | R50: =_xlfn.PERCENTRANK.INC(Raw_Data!$R$2:$R$60, Raw_Data!R50) -> 0.083 | S50: =_xlfn.PERCENTRANK.INC(Raw_Data!$S$2:$S$60, Raw_Data!S50) -> 0.083 | T50: =_xlfn.PERCENTRANK.INC(Raw_Data!$T$2:$T$60, Raw_Data!T50) -> 0.041 | U50: =_xlfn.PERCENTRANK.INC(Raw_Data!$U$2:$U$60, Raw_Data!U50) -> 0.104

Sheet Archetype_Scores
A1: Player | B1: Box_Dominator | C1: Buildup_Striker | D1: Transition_Outlet | E1: Back_To_Goal
A2: =Normalized!A34 -> Rodrigo Muniz | B2: =0.3*Normalized!H34 +0.3*Normalized!F34 +0.15*Normalized!I34 +0.15*Normalized!K34 +0.1*Normalized!L34 -> 0.81005 | C2: =0.3*Normalized!P34 +0.3*Normalized!R34 +0.25*Normalized!Q34 +0.15*Normalized!H34 -> 0.23805 | D2: =0.3*Normalized!S34 +0.3*Normalized!T34 +0.25*Normalized!U34 +0.15*Normalized!E34 -> 0.15285 | E2: =0.35*Normalized!J34 +0.25*Normalized!L34 +0.25*Normalized!P34 +0.15*Normalized!H34 -> 0.5755
A3: =Normalized!A9 -> Beto | B3: =0.3*Normalized!H9 +0.3*Normalized!F9 +0.15*Normalized!I9 +0.15*Normalized!K9 +0.1*Normalized!L9 -> 0.80475 | C3: =0.3*Normalized!P9 +0.3*Normalized!R9 +0.25*Normalized!Q9 +0.15*Normalized!H9 -> 0.23195 | D3: =0.3*Normalized!S9 +0.3*Normalized!T9 +0.25*Normalized!U9 +0.15*Normalized!E9 -> 0.3184 | E3: =0.35*Normalized!J9 +0.25*Normalized!L9 +0.25*Normalized!P9 +0.15*Normalized!H9 -> 0.6508
A4: =Normalized!A36 -> Darwin Núñez | B4: =0.3*Normalized!H36 +0.3*Normalized!F36 +0.15*Normalized!I36 +0.15*Normalized!K36 +0.1*Normalized!L36 -> 0.76295 | C4: =0.3*Normalized!P36 +0.3*Normalized!R36 +0.25*Normalized!Q36 +0.15*Normalized!H36 -> 0.6702 | D4: =0.3*Normalized!S36 +0.3*Normalized!T36 +0.25*Normalized!U36 +0.15*Normalized!E36 -> 0.58705 | E4: =0.35*Normalized!J36 +0.25*Normalized!L36 +0.25*Normalized!P36 +0.15*Normalized!H36 -> 0.441
A5: =Normalized!A38 -> Richarlison | B5: =0.3*Normalized!H38 +0.3*Normalized!F38 +0.15*Normalized!I38 +0.15*Normalized!K38 +0.1*Normalized!L38 -> 0.761 | C5: =0.3*Normalized!P38 +0.3*Normalized!R38 +0.25*Normalized!Q38 +0.15*Normalized!H38 -> 0.3985 | D5: =0.3*Normalized!S38 +0.3*Normalized!T38 +0.25*Normalized!U38 +0.15*Normalized!E38 -> 0.41205 | E5: =0.35*Normalized!J38 +0.25*Normalized!L38 +0.25*Normalized!P38 +0.15*Normalized!H38 -> 0.5163
A6: =Normalized!A17 -> Erling Haaland | B6: =0.3*Normalized!H17 +0.3*Normalized!F17 +0.15*Normalized!I17 +0.15*Normalized!K17 +0.1*Normalized!L17 -> 0.7561 | C6: =0.3*Normalized!P17 +0.3*Normalized!R17 +0.25*Normalized!Q17 +0.15*Normalized!H17 -> 0.3568 | D6: =0.3*Normalized!S17 +0.3*Normalized!T17 +0.25*Normalized!U17 +0.15*Normalized!E17 -> 0.3224 | E6: =0.35*Normalized!J17 +0.25*Normalized!L17 +0.25*Normalized!P17 +0.15*Normalized!H17 -> 0.48615
A7: =Normalized!A47 -> Callum Wilson | B7: =0.3*Normalized!H47 +0.3*Normalized!F47 +0.15*Normalized!I47 +0.15*Normalized!K47 +0.1*Normalized!L47 -> 0.68275 | C7: =0.3*Normalized!P47 +0.3*Normalized!R47 +0.25*Normalized!Q47 +0.15*Normalized!H47 -> 0.24845 | D7: =0.3*Normalized!S47 +0.3*Normalized!T47 +0.25*Normalized!U47 +0.15*Normalized!E47 -> 0.2497 | E7: =0.35*Normalized!J47 +0.25*Normalized!L47 +0.25*Normalized!P47 +0.15*Normalized!H47 -> 0.4901
A8: =Normalized!A11 -> Dominic Calvert-Lewin | B8: =0.3*Normalized!H11 +0.3*Normalized!F11 +0.15*Normalized!I11 +0.15*Normalized!K11 +0.1*Normalized!L11 -> 0.68075 | C8: =0.3*Normalized!P11 +0.3*Normalized!R11 +0.25*Normalized!Q11 +0.15*Normalized!H11 -> 0.35595 | D8: =0.3*Normalized!S11 +0.3*Normalized!T11 +0.25*Normalized!U11 +0.15*Normalized!E11 -> 0.3599 | E8: =0.35*Normalized!J11 +0.25*Normalized!L11 +0.25*Normalized!P11 +0.15*Normalized!H11 -> 0.586
A9: =Normalized!A31 -> Oliver McBurnie | B9: =0.3*Normalized!H31 +0.3*Normalized!F31 +0.15*Normalized!I31 +0.15*Normalized!K31 +0.1*Normalized!L31 -> 0.6518 | C9: =0.3*Normalized!P31 +0.3*Normalized!R31 +0.25*Normalized!Q31 +0.15*Normalized!H31 -> 0.28885 | D9: =0.3*Normalized!S31 +0.3*Normalized!T31 +0.25*Normalized!U31 +0.15*Normalized!E31 -> 0.0465 | E9: =0.35*Normalized!J31 +0.25*Normalized!L31 +0.25*Normalized!P31 +0.15*Normalized!H31 -> 0.7568
A10: =Normalized!A39 -> Bukayo Saka | B10: =0.3*Normalized!H39 +0.3*Normalized!F39 +0.15*Normalized!I39 +0.15*Normalized!K39 +0.1*Normalized!L39 -> 0.6436 | C10: =0.3*Normalized!P39 +0.3*Normalized!R39 +0.25*Normalized!Q39 +0.15*Normalized!H39 -> 0.96865 | D10: =0.3*Normalized!S39 +0.3*Normalized!T39 +0.25*Normalized!U39 +0.15*Normalized!E39 -> 0.8641 | E10: =0.35*Normalized!J39 +0.25*Normalized!L39 +0.25*Normalized!P39 +0.15*Normalized!H39 -> 0.80905
A11: =Normalized!A35 -> Eddie Nketiah | B11: =0.3*Normalized!H35 +0.3*Normalized!F35 +0.15*Normalized!I35 +0.15*Normalized!K35 +0.1*Normalized!L35 -> 0.6403 | C11: =0.3*Normalized!P35 +0.3*Normalized!R35 +0.25*Normalized!Q35 +0.15*Normalized!H35 -> 0.2339 | D11: =0.3*Normalized!S35 +0.3*Normalized!T35 +0.25*Normalized!U35 +0.15*Normalized!E35 -> 0.35885 | E11: =0.35*Normalized!J35 +0.25*Normalized!L35 +0.25*Normalized!P35 +0.15*Normalized!H35 -> 0.7163
A12: =Normalized!A40 -> Mohamed Salah | B12: =0.3*Normalized!H40 +0.3*Normalized!F40 +0.15*Normalized!I40 +0.15*Normalized!K40 +0.1*Normalized!L40 -> 0.6371 | C12: =0.3*Normalized!P40 +0.3*Normalized!R40 +0.25*Normalized!Q40 +0.15*Normalized!H40 -> 0.9391 | D12: =0.3*Normalized!S40 +0.3*Normalized!T40 +0.25*Normalized!U40 +0.15*Normalized!E40 -> 0.7534 | E12: =0.35*Normalized!J40 +0.25*Normalized!L40 +0.25*Normalized!P40 +0.15*Normalized!H40 -> 0.4715
A13: =Normalized!A42 -> Dominic Solanke | B13: =0.3*Normalized!H42 +0.3*Normalized!F42 +0.15*Normalized!I42 +0.15*Normalized!K42 +0.1*Normalized!L42 -> 0.63705 | C13: =0.3*Normalized!P42 +0.3*Normalized!R42 +0.25*Normalized!Q42 +0.15*Normalized!H42 -> 0.50465 | D13: =0.3*Normalized!S42 +0.3*Normalized!T42 +0.25*Normalized!U42 +0.15*Normalized!E42 -> 0.3748 | E13: =0.35*Normalized!J42 +0.25*Normalized!L42 +0.25*Normalized!P42 +0.15*Normalized!H42 -> 0.4319
A14: =Normalized!A25 -> Diogo Jota | B14: =0.3*Normalized!H25 +0.3*Normalized!F25 +0.15*Normalized!I25 +0.15*Normalized!K25 +0.1*Normalized!L25 -> 0.63195 | C14: =0.3*Normalized!P25 +0.3*Normalized!R25 +0.25*Normalized!Q25 +0.15*Normalized!H25 -> 0.54135 | D14: =0.3*Normalized!S25 +0.3*Normalized!T25 +0.25*Normalized!U25 +0.15*Normalized!E25 -> 0.69755 | E14: =0.35*Normalized!J25 +0.25*Normalized!L25 +0.25*Normalized!P25 +0.15*Normalized!H25 -> 0.5775
A15: =Normalized!A22 -> Gabriel Jesus | B15: =0.3*Normalized!H22 +0.3*Normalized!F22 +0.15*Normalized!I22 +0.15*Normalized!K22 +0.1*Normalized!L22 -> 0.6205 | C15: =0.3*Normalized!P22 +0.3*Normalized!R22 +0.25*Normalized!Q22 +0.15*Normalized!H22 -> 0.688 | D15: =0.3*Normalized!S22 +0.3*Normalized!T22 +0.25*Normalized!U22 +0.15*Normalized!E22 -> 0.5641 | E15: =0.35*Normalized!J22 +0.25*Normalized!L22 +0.25*Normalized!P22 +0.15*Normalized!H22 -> 0.6254
A16: =Normalized!A21 -> Nicolas Jackson | B16: =0.3*Normalized!H21 +0.3*Normalized!F21 +0.15*Normalized!I21 +0.15*Normalized!K21 +0.1*Normalized!L21 -> 0.6047 | C16: =0.3*Normalized!P21 +0.3*Normalized!R21 +0.25*Normalized!Q21 +0.15*Normalized!H21 -> 0.59025 | D16: =0.3*Normalized!S21 +0.3*Normalized!T21 +0.25*Normalized!U21 +0.15*Normalized!E21 -> 0.5161 | E16: =0.35*Normalized!J21 +0.25*Normalized!L21 +0.25*Normalized!P21 +0.15*Normalized!H21 -> 0.40235
A17: =Normalized!A13 -> Luis Díaz | B17: =0.3*Normalized!H13 +0.3*Normalized!F13 +0.15*Normalized!I13 +0.15*Normalized!K13 +0.1*Normalized!L13 -> 0.58915 | C17: =0.3*Normalized!P13 +0.3*Normalized!R13 +0.25*Normalized!Q13 +0.15*Normalized!H13 -> 0.8902 | D17: =0.3*Normalized!S13 +0.3*Normalized!T13 +0.25*Normalized!U13 +0.15*Normalized!E13 -> 0.87475 | E17: =0.35*Normalized!J13 +0.25*Normalized!L13 +0.25*Normalized!P13 +0.15*Normalized!H13 -> 0.5997
A18: =Normalized!A45 -> Ollie Watkins | B18: =0.3*Normalized!H45 +0.3*Normalized!F45 +0.15*Normalized!I45 +0.15*Normalized!K45 +0.1*Normalized!L45 -> 0.5862 | C18: =0.3*Normalized!P45 +0.3*Normalized!R45 +0.25*Normalized!Q45 +0.15*Normalized!H45 -> 0.59225 | D18: =0.3*Normalized!S45 +0.3*Normalized!T45 +0.25*Normalized!U45 +0.15*Normalized!E45 -> 0.4851 | E18: =0.35*Normalized!J45 +0.25*Normalized!L45 +0.25*Normalized!P45 +0.15*Normalized!H45 -> 0.38685
A19: =Normalized!A50 -> Chris Wood | B19: =0.3*Normalized!H50 +0.3*Normalized!F50 +0.15*Normalized!I50 +0.15*Normalized!K50 +0.1*Normalized!L50 -> 0.5861 | C19: =0.3*Normalized!P50 +0.3*Normalized!R50 +0.25*Normalized!Q50 +0.15*Normalized!H50 -> 0.25695 | D19: =0.3*Normalized!S50 +0.3*Normalized!T50 +0.25*Normalized!U50 +0.15*Normalized!E50 -> 0.11945 | E19: =0.35*Normalized!J50 +0.25*Normalized!L50 +0.25*Normalized!P50 +0.15*Normalized!H50 -> 0.39545
A20: =Normalized!A20 -> Alexander Isak | B20: =0.3*Normalized!H20 +0.3*Normalized!F20 +0.15*Normalized!I20 +0.15*Normalized!K20 +0.1*Normalized!L20 -> 0.58095 | C20: =0.3*Normalized!P20 +0.3*Normalized!R20 +0.25*Normalized!Q20 +0.15*Normalized!H20 -> 0.3716 | D20: =0.3*Normalized!S20 +0.3*Normalized!T20 +0.25*Normalized!U20 +0.15*Normalized!E20 -> 0.5757 | E20: =0.35*Normalized!J20 +0.25*Normalized!L20 +0.25*Normalized!P20 +0.15*Normalized!H20 -> 0.1299
A21: =Normalized!A44 -> Ivan Toney | B21: =0.3*Normalized!H44 +0.3*Normalized!F44 +0.15*Normalized!I44 +0.15*Normalized!K44 +0.1*Normalized!L44 -> 0.56325 | C21: =0.3*Normalized!P44 +0.3*Normalized!R44 +0.25*Normalized!Q44 +0.15*Normalized!H44 -> 0.29875 | D21: =0.3*Normalized!S44 +0.3*Normalized!T44 +0.25*Normalized!U44 +0.15*Normalized!E44 -> 0.3589 | E21: =0.35*Normalized!J44 +0.25*Normalized!L44 +0.25*Normalized!P44 +0.15*Normalized!H44 -> 0.658
A22: =Normalized!A30 -> Bryan Mbeumo | B22: =0.3*Normalized!H30 +0.3*Normalized!F30 +0.15*Normalized!I30 +0.15*Normalized!K30 +0.1*Normalized!L30 -> 0.55895 | C22: =0.3*Normalized!P30 +0.3*Normalized!R30 +0.25*Normalized!Q30 +0.15*Normalized!H30 -> 0.65475 | D22: =0.3*Normalized!S30 +0.3*Normalized!T30 +0.25*Normalized!U30 +0.15*Normalized!E30 -> 0.6132 | E22: =0.35*Normalized!J30 +0.25*Normalized!L30 +0.25*Normalized!P30 +0.15*Normalized!H30 -> 0.56735
A23: =Normalized!A29 -> Neal Maupay | B23: =0.3*Normalized!H29 +0.3*Normalized!F29 +0.15*Normalized!I29 +0.15*Normalized!K29 +0.1*Normalized!L29 -> 0.51855 | C23: =0.3*Normalized!P29 +0.3*Normalized!R29 +0.25*Normalized!Q29 +0.15*Normalized!H29 -> 0.29545 | D23: =0.3*Normalized!S29 +0.3*Normalized!T29 +0.25*Normalized!U29 +0.15*Normalized!E29 -> 0.26935 | E23: =0.35*Normalized!J29 +0.25*Normalized!L29 +0.25*Normalized!P29 +0.15*Normalized!H29 -> 0.381
A24: =Normalized!A49 -> Yoane Wissa | B24: =0.3*Normalized!H49 +0.3*Normalized!F49 +0.15*Normalized!I49 +0.15*Normalized!K49 +0.1*Normalized!L49 -> 0.5132 | C24: =0.3*Normalized!P49 +0.3*Normalized!R49 +0.25*Normalized!Q49 +0.15*Normalized!H49 -> 0.36295 | D24: =0.3*Normalized!S49 +0.3*Normalized!T49 +0.25*Normalized!U49 +0.15*Normalized!E49 -> 0.37485 | E24: =0.35*Normalized!J49 +0.25*Normalized!L49 +0.25*Normalized!P49 +0.15*Normalized!H49 -> 0.52325
A25: =Normalized!A23 -> Raúl Jiménez | B25: =0.3*Normalized!H23 +0.3*Normalized!F23 +0.15*Normalized!I23 +0.15*Normalized!K23 +0.1*Normalized!L23 -> 0.5015 | C25: =0.3*Normalized!P23 +0.3*Normalized!R23 +0.25*Normalized!Q23 +0.15*Normalized!H23 -> 0.26 | D25: =0.3*Normalized!S23 +0.3*Normalized!T23 +0.25*Normalized!U23 +0.15*Normalized!E23 -> 0.16295 | E25: =0.35*Normalized!J23 +0.25*Normalized!L23 +0.25*Normalized!P23 +0.15*Normalized!H23 -> 0.54425
A26: =Normalized!A15 -> Alejandro Garnacho | B26: =0.3*Normalized!H15 +0.3*Normalized!F15 +0.15*Normalized!I15 +0.15*Normalized!K15 +0.1*Normalized!L15 -> 0.4841 | C26: =0.3*Normalized!P15 +0.3*Normalized!R15 +0.25*Normalized!Q15 +0.15*Normalized!H15 -> 0.878 | D26: =0.3*Normalized!S15 +0.3*Normalized!T15 +0.25*Normalized!U15 +0.15*Normalized!E15 -> 0.95605 | E26: =0.35*Normalized!J15 +0.25*Normalized!L15 +0.25*Normalized!P15 +0.15*Normalized!H15 -> 0.5651
A27: =Normalized!A24 -> Brennan Johnson | B27: =0.3*Normalized!H24 +0.3*Normalized!F24 +0.15*Normalized!I24 +0.15*Normalized!K24 +0.1*Normalized!L24 -> 0.4767 | C27: =0.3*Normalized!P24 +0.3*Normalized!R24 +0.25*Normalized!Q24 +0.15*Normalized!H24 -> 0.77675 | D27: =0.3*Normalized!S24 +0.3*Normalized!T24 +0.25*Normalized!U24 +0.15*Normalized!E24 -> 0.64535 | E27: =0.35*Normalized!J24 +0.25*Normalized!L24 +0.25*Normalized!P24 +0.15*Normalized!H24 -> 0.38105
A28: =Normalized!A27 -> Gabriel Martinelli | B28: =0.3*Normalized!H27 +0.3*Normalized!F27 +0.15*Normalized!I27 +0.15*Normalized!K27 +0.1*Normalized!L27 -> 0.46 | C28: =0.3*Normalized!P27 +0.3*Normalized!R27 +0.25*Normalized!Q27 +0.15*Normalized!H27 -> 0.94355 | D28: =0.3*Normalized!S27 +0.3*Normalized!T27 +0.25*Normalized!U27 +0.15*Normalized!E27 -> 0.8818 | E28: =0.35*Normalized!J27 +0.25*Normalized!L27 +0.25*Normalized!P27 +0.15*Normalized!H27 -> 0.6018
A29: =Normalized!A8 -> Taiwo Awoniyi | B29: =0.3*Normalized!H8 +0.3*Normalized!F8 +0.15*Normalized!I8 +0.15*Normalized!K8 +0.1*Normalized!L8 -> 0.45395 | C29: =0.3*Normalized!P8 +0.3*Normalized!R8 +0.25*Normalized!Q8 +0.15*Normalized!H8 -> 0.0581 | D29: =0.3*Normalized!S8 +0.3*Normalized!T8 +0.25*Normalized!U8 +0.15*Normalized!E8 -> 0.083 | E29: =0.35*Normalized!J8 +0.25*Normalized!L8 +0.25*Normalized!P8 +0.15*Normalized!H8 -> 0.23415
A30: =Normalized!A10 -> Jarrod Bowen | B30: =0.3*Normalized!H10 +0.3*Normalized!F10 +0.15*Normalized!I10 +0.15*Normalized!K10 +0.1*Normalized!L10 -> 0.44535 | C30: =0.3*Normalized!P10 +0.3*Normalized!R10 +0.25*Normalized!Q10 +0.15*Normalized!H10 -> 0.5092 | D30: =0.3*Normalized!S10 +0.3*Normalized!T10 +0.25*Normalized!U10 +0.15*Normalized!E10 -> 0.57245 | E30: =0.35*Normalized!J10 +0.25*Normalized!L10 +0.25*Normalized!P10 +0.15*Normalized!H10 -> 0.31945
A31: =Normalized!A28 -> Jean-Philippe Mateta | B31: =0.3*Normalized!H28 +0.3*Normalized!F28 +0.15*Normalized!I28 +0.15*Normalized!K28 +0.1*Normalized!L28 -> 0.43805 | C31: =0.3*Normalized!P28 +0.3*Normalized!R28 +0.25*Normalized!Q28 +0.15*Normalized!H28 -> 0.3765 | D31: =0.3*Normalized!S28 +0.3*Normalized!T28 +0.25*Normalized!U28 +0.15*Normalized!E28 -> 0.16695 | E31: =0.35*Normalized!J28 +0.25*Normalized!L28 +0.25*Normalized!P28 +0.15*Normalized!H28 -> 0.35175
A32: =Normalized!A41 -> Antoine Semenyo | B32: =0.3*Normalized!H41 +0.3*Normalized!F41 +0.15*Normalized!I41 +0.15*Normalized!K41 +0.1*Normalized!L41 -> 0.436 | C32: =0.3*Normalized!P41 +0.3*Normalized!R41 +0.25*Normalized!Q41 +0.15*Normalized!H41 -> 0.5848 | D32: =0.3*Normalized!S41 +0.3*Normalized!T41 +0.25*Normalized!U41 +0.15*Normalized!E41 -> 0.74055 | E32: =0.35*Normalized!J41 +0.25*Normalized!L41 +0.25*Normalized!P41 +0.15*Normalized!H41 -> 0.47455
A33: =Normalized!A2 -> Elijah Adebayo | B33: =0.3*Normalized!H2 +0.3*Normalized!F2 +0.15*Normalized!I2 +0.15*Normalized!K2 +0.1*Normalized!L2 -> 0.4351 | C33: =0.3*Normalized!P2 +0.3*Normalized!R2 +0.25*Normalized!Q2 +0.15*Normalized!H2 -> 0.2683 | D33: =0.3*Normalized!S2 +0.3*Normalized!T2 +0.25*Normalized!U2 +0.15*Normalized!E2 -> 0.1339 | E33: =0.35*Normalized!J2 +0.25*Normalized!L2 +0.25*Normalized!P2 +0.15*Normalized!H2 -> 0.50275
A34: =Normalized!A16 -> Anthony Gordon | B34: =0.3*Normalized!H16 +0.3*Normalized!F16 +0.15*Normalized!I16 +0.15*Normalized!K16 +0.1*Normalized!L16 -> 0.4132 | C34: =0.3*Normalized!P16 +0.3*Normalized!R16 +0.25*Normalized!Q16 +0.15*Normalized!H16 -> 0.70375 | D34: =0.3*Normalized!S16 +0.3*Normalized!T16 +0.25*Normalized!U16 +0.15*Normalized!E16 -> 0.75575 | E34: =0.35*Normalized!J16 +0.25*Normalized!L16 +0.25*Normalized!P16 +0.15*Normalized!H16 -> 0.5465
A35: =Normalized!A18 -> Son Heung-min | B35: =0.3*Normalized!H18 +0.3*Normalized!F18 +0.15*Normalized!I18 +0.15*Normalized!K18 +0.1*Normalized!L18 -> 0.39735 | C35: =0.3*Normalized!P18 +0.3*Normalized!R18 +0.25*Normalized!Q18 +0.15*Normalized!H18 -> 0.85705 | D35: =0.3*Normalized!S18 +0.3*Normalized!T18 +0.25*Normalized!U18 +0.15*Normalized!E18 -> 0.69365 | E35: =0.35*Normalized!J18 +0.25*Normalized!L18 +0.25*Normalized!P18 +0.15*Normalized!H18 -> 0.3955
A36: =Normalized!A32 -> Kaoru Mitoma | B36: =0.3*Normalized!H32 +0.3*Normalized!F32 +0.15*Normalized!I32 +0.15*Normalized!K32 +0.1*Normalized!L32 -> 0.3779 | C36: =0.3*Normalized!P32 +0.3*Normalized!R32 +0.25*Normalized!Q32 +0.15*Normalized!H32 -> 0.77255 | D36: =0.3*Normalized!S32 +0.3*Normalized!T32 +0.25*Normalized!U32 +0.15*Normalized!E32 -> 0.83315 | E36: =0.35*Normalized!J32 +0.25*Normalized!L32 +0.25*Normalized!P32 +0.15*Normalized!H32 -> 0.82475
A37: =Normalized!A26 -> Noni Madueke | B37: =0.3*Normalized!H26 +0.3*Normalized!F26 +0.15*Normalized!I26 +0.15*Normalized!K26 +0.1*Normalized!L26 -> 0.3778 | C37: =0.3*Normalized!P26 +0.3*Normalized!R26 +0.25*Normalized!Q26 +0.15*Normalized!H26 -> 0.63 | D37: =0.3*Normalized!S26 +0.3*Normalized!T26 +0.25*Normalized!U26 +0.15*Normalized!E26 -> 0.8382 | E37: =0.35*Normalized!J26 +0.25*Normalized!L26 +0.25*Normalized!P26 +0.15*Normalized!H26 -> 0.74345
A38: =Normalized!A14 -> Evan Ferguson | B38: =0.3*Normalized!H14 +0.3*Normalized!F14 +0.15*Normalized!I14 +0.15*Normalized!K14 +0.1*Normalized!L14 -> 0.3639 | C38: =0.3*Normalized!P14 +0.3*Normalized!R14 +0.25*Normalized!Q14 +0.15*Normalized!H14 -> 0.0903 | D38: =0.3*Normalized!S14 +0.3*Normalized!T14 +0.25*Normalized!U14 +0.15*Normalized!E14 -> 0.11015 | E38: =0.35*Normalized!J14 +0.25*Normalized!L14 +0.25*Normalized!P14 +0.15*Normalized!H14 -> 0.4693
A39: =Normalized!A6 -> Michail Antonio | B39: =0.3*Normalized!H6 +0.3*Normalized!F6 +0.15*Normalized!I6 +0.15*Normalized!K6 +0.1*Normalized!L6 -> 0.35995 | C39: =0.3*Normalized!P6 +0.3*Normalized!R6 +0.25*Normalized!Q6 +0.15*Normalized!H6 -> 0.1388 | D39: =0.3*Normalized!S6 +0.3*Normalized!T6 +0.25*Normalized!U6 +0.15*Normalized!E6 -> 0.3789 | E39: =0.35*Normalized!J6 +0.25*Normalized!L6 +0.25*Normalized!P6 +0.15*Normalized!H6 -> 0.3775
A40: =Normalized!A12 -> Bobby De Cordova-Reid | B40: =0.3*Normalized!H12 +0.3*Normalized!F12 +0.15*Normalized!I12 +0.15*Normalized!K12 +0.1*Normalized!L12 -> 0.34135 | C40: =0.3*Normalized!P12 +0.3*Normalized!R12 +0.25*Normalized!Q12 +0.15*Normalized!H12 -> 0.3204 | D40: =0.3*Normalized!S12 +0.3*Normalized!T12 +0.25*Normalized!U12 +0.15*Normalized!E12 -> 0.3152 | E40: =0.35*Normalized!J12 +0.25*Normalized!L12 +0.25*Normalized!P12 +0.15*Normalized!H12 -> 0.43835
...

Sheet Player_Profile
A1: Player Profile
A3: Select Player: | B3: Erling Haaland | D3: Team: | E3: =_xlfn.XLOOKUP($B$3, Raw_Data!A:A, Raw_Data!B:B) -> Manchester City
D4: Age: | E4: =_xlfn.XLOOKUP($B$3, Raw_Data!A:A, Raw_Data!C:C) -> 23
D5: Minutes: | E5: =_xlfn.XLOOKUP($B$3, Raw_Data!A:A, Raw_Data!D:D) -> 2552
A6: Box Dominator | B6: =_xlfn.XLOOKUP($B$3, Archetype_Scores!$A:$A, Archetype_Scores!B:B) -> 0.7561 | G6: Strengths
A7: Buildup Striker | B7: =_xlfn.XLOOKUP($B$3, Archetype_Scores!$A:$A, Archetype_Scores!C:C) -> 0.3568
A8: Transition Outlet | B8: =_xlfn.XLOOKUP($B$3, Archetype_Scores!$A:$A, Archetype_Scores!D:D) -> 0.3224
A9: Back-to-Goal | B9: =_xlfn.XLOOKUP($B$3, Archetype_Scores!$A:$A, Archetype_Scores!E:E) -> 0.48615
G12: Risks / Notes

Sheet Shortlist_Comparison
A1: Player | B1: Age | C1: Minutes | D1: Box_Dominator | E1: Buildup_Striker | F1: Transition_Outlet | G1: Back_to_Goal | H1: Overall_Fit
A2: =Archetype_Scores!A2 -> Rodrigo Muniz | B2: =_xlfn.XLOOKUP(A2, Raw_Data!A:A, Raw_Data!C:C) -> 22 | C2: =_xlfn.XLOOKUP(A2, Raw_Data!A:A, Raw_Data!D:D) -> 1593 | D2: =_xlfn.XLOOKUP(A2, Archetype_Scores!A:A, Archetype_Scores!B:B) -> 0.81005 | E2: =_xlfn.XLOOKUP(A2, Archetype_Scores!A:A, Archetype_Scores!C:C) -> 0.23805 | F2: =_xlfn.XLOOKUP(A2, Archetype_Scores!A:A, Archetype_Scores!D:D) -> 0.15285 | G2: =_xlfn.XLOOKUP(A2, Archetype_Scores!A:A, Archetype_Scores!E:E) -> 0.5755 | J2: Give weight to whatever you find most valuable to your team.
A3: =Archetype_Scores!A3 -> Beto | B3: =_xlfn.XLOOKUP(A3, Raw_Data!A:A, Raw_Data!C:C) -> 25 | C3: =_xlfn.XLOOKUP(A3, Raw_Data!A:A, Raw_Data!D:D) -> 951 | D3: =_xlfn.XLOOKUP(A3, Archetype_Scores!A:A, Archetype_Scores!B:B) -> 0.80475 | E3: =_xlfn.XLOOKUP(A3, Archetype_Scores!A:A, Archetype_Scores!C:C) -> 0.23195 | F3: =_xlfn.XLOOKUP(A3, Archetype_Scores!A:A, Archetype_Scores!D:D) -> 0.3184 | G3: =_xlfn.XLOOKUP(A3, Archetype_Scores!A:A, Archetype_Scores!E:E) -> 0.6508 | J3: Box Dominators | K3: 0.50*D2+0.20*G2+0.20*E2+0.10*F2
A4: =Archetype_Scores!A4 -> Darwin Núñez | B4: =_xlfn.XLOOKUP(A4, Raw_Data!A:A, Raw_Data!C:C) -> 24 | C4: =_xlfn.XLOOKUP(A4, Raw_Data!A:A, Raw_Data!D:D) -> 2047 | D4: =_xlfn.XLOOKUP(A4, Archetype_Scores!A:A, Archetype_Scores!B:B) -> 0.76295 | E4: =_xlfn.XLOOKUP(A4, Archetype_Scores!A:A, Archetype_Scores!C:C) -> 0.6702 | F4: =_xlfn.XLOOKUP(A4, Archetype_Scores!A:A, Archetype_Scores!D:D) -> 0.58705 | G4: =_xlfn.XLOOKUP(A4, Archetype_Scores!A:A, Archetype_Scores!E:E) -> 0.441 | J4: Back To Goal | K4: 0.10*D2+0.50*G2+0.20*E2+0.20*F2
A5: =Archetype_Scores!A5 -> Richarlison | B5: =_xlfn.XLOOKUP(A5, Raw_Data!A:A, Raw_Data!C:C) -> 26 | C5: =_xlfn.XLOOKUP(A5, Raw_Data!A:A, Raw_Data!D:D) -> 1491 | D5: =_xlfn.XLOOKUP(A5, Archetype_Scores!A:A, Archetype_Scores!B:B) -> 0.761 | E5: =_xlfn.XLOOKUP(A5, Archetype_Scores!A:A, Archetype_Scores!C:C) -> 0.3985 | F5: =_xlfn.XLOOKUP(A5, Archetype_Scores!A:A, Archetype_Scores!D:D) -> 0.41205 | G5: =_xlfn.XLOOKUP(A5, Archetype_Scores!A:A, Archetype_Scores!E:E) -> 0.5163 | J5: Buildup Striker | K5: 0.20*D2+0.20*G2+0.50*E2+0.10*F2
A6: =Archetype_Scores!A6 -> Erling Haaland | B6: =_xlfn.XLOOKUP(A6, Raw_Data!A:A, Raw_Data!C:C) -> 23 | C6: =_xlfn.XLOOKUP(A6, Raw_Data!A:A, Raw_Data!D:D) -> 2552 | D6: =_xlfn.XLOOKUP(A6, Archetype_Scores!A:A, Archetype_Scores!B:B) -> 0.7561 | E6: =_xlfn.XLOOKUP(A6, Archetype_Scores!A:A, Archetype_Scores!C:C) -> 0.3568 | F6: =_xlfn.XLOOKUP(A6, Archetype_Scores!A:A, Archetype_Scores!D:D) -> 0.3224 | G6: =_xlfn.XLOOKUP(A6, Archetype_Scores!A:A, Archetype_Scores!E:E) -> 0.48615 | J6: Transition Outlet | K6: 0.20*D2+0.10*G2+0.20*E2+0.50*F2
A7: =Archetype_Scores!A7 -> Callum Wilson | B7: =_xlfn.XLOOKUP(A7, Raw_Data!A:A, Raw_Data!C:C) -> 31 | C7: =_xlfn.XLOOKUP(A7, Raw_Data!A:A, Raw_Data!D:D) -> 991 | D7: =_xlfn.XLOOKUP(A7, Archetype_Scores!A:A, Archetype_Scores!B:B) -> 0.68275 | E7: =_xlfn.XLOOKUP(A7, Archetype_Scores!A:A, Archetype_Scores!C:C) -> 0.24845 | F7: =_xlfn.XLOOKUP(A7, Archetype_Scores!A:A, Archetype_Scores!D:D) -> 0.2497 | G7: =_xlfn.XLOOKUP(A7, Archetype_Scores!A:A, Archetype_Scores!E:E) -> 0.4901
A8: =Archetype_Scores!A8 -> Dominic Calvert-Lewin | B8: =_xlfn.XLOOKUP(A8, Raw_Data!A:A, Raw_Data!C:C) -> 26 | C8: =_xlfn.XLOOKUP(A8, Raw_Data!A:A, Raw_Data!D:D) -> 2171 | D8: =_xlfn.XLOOKUP(A8, Archetype_Scores!A:A, Archetype_Scores!B:B) -> 0.68075 | E8: =_xlfn.XLOOKUP(A8, Archetype_Scores!A:A, Archetype_Scores!C:C) -> 0.35595 | F8: =_xlfn.XLOOKUP(A8, Archetype_Scores!A:A, Archetype_Scores!D:D) -> 0.3599 | G8: =_xlfn.XLOOKUP(A8, Archetype_Scores!A:A, Archetype_Scores!E:E) -> 0.586
A9: =Archetype_Scores!A9 -> Oliver McBurnie | B9: =_xlfn.XLOOKUP(A9, Raw_Data!A:A, Raw_Data!C:C) -> 27 | C9: =_xlfn.XLOOKUP(A9, Raw_Data!A:A, Raw_Data!D:D) -> 1280 | D9: =_xlfn.XLOOKUP(A9, Archetype_Scores!A:A, Archetype_Scores!B:B) -> 0.6518 | E9: =_xlfn.XLOOKUP(A9, Archetype_Scores!A:A, Archetype_Scores!C:C) -> 0.28885 | F9: =_xlfn.XLOOKUP(A9, Archetype_Scores!A:A, Archetype_Scores!D:D) -> 0.0465 | G9: =_xlfn.XLOOKUP(A9, Archetype_Scores!A:A, Archetype_Scores!E:E) -> 0.7568
A10: =Archetype_Scores!A10 -> Bukayo Saka | B10: =_xlfn.XLOOKUP(A10, Raw_Data!A:A, Raw_Data!C:C) -> 21 | C10: =_xlfn.XLOOKUP(A10, Raw_Data!A:A, Raw_Data!D:D) -> 2919 | D10: =_xlfn.XLOOKUP(A10, Archetype_Scores!A:A, Archetype_Scores!B:B) -> 0.6436 | E10: =_xlfn.XLOOKUP(A10, Archetype_Scores!A:A, Archetype_Scores!C:C) -> 0.96865 | F10: =_xlfn.XLOOKUP(A10, Archetype_Scores!A:A, Archetype_Scores!D:D) -> 0.8641 | G10: =_xlfn.XLOOKUP(A10, Archetype_Scores!A:A, Archetype_Scores!E:E) -> 0.80905
A11: =Archetype_Scores!A11 -> Eddie Nketiah | B11: =_xlfn.XLOOKUP(A11, Raw_Data!A:A, Raw_Data!C:C) -> 24 | C11: =_xlfn.XLOOKUP(A11, Raw_Data!A:A, Raw_Data!D:D) -> 1082 | D11: =_xlfn.XLOOKUP(A11, Archetype_Scores!A:A, Archetype_Scores!B:B) -> 0.6403 | E11: =_xlfn.XLOOKUP(A11, Archetype_Scores!A:A, Archetype_Scores!C:C) -> 0.2339 | F11: =_xlfn.XLOOKUP(A11, Archetype_Scores!A:A, Archetype_Scores!D:D) -> 0.35885 | G11: =_xlfn.XLOOKUP(A11, Archetype_Scores!A:A, Archetype_Scores!E:E) -> 0.7163
A12: =Archetype_Scores!A12 -> Mohamed Salah | B12: =_xlfn.XLOOKUP(A12, Raw_Data!A:A, Raw_Data!C:C) -> 31 | C12: =_xlfn.XLOOKUP(A12, Raw_Data!A:A, Raw_Data!D:D) -> 2534 | D12: =_xlfn.XLOOKUP(A12, Archetype_Scores!A:A, Archetype_Scores!B:B) -> 0.6371 | E12: =_xlfn.XLOOKUP(A12, Archetype_Scores!A:A, Archetype_Scores!C:C) -> 0.9391 | F12: =_xlfn.XLOOKUP(A12, Archetype_Scores!A:A, Archetype_Scores!D:D) -> 0.7534 | G12: =_xlfn.XLOOKUP(A12, Archetype_Scores!A:A, Archetype_Scores!E:E) -> 0.4715
A13: =Archetype_Scores!A13 -> Dominic Solanke | B13: =_xlfn.XLOOKUP(A13, Raw_Data!A:A, Raw_Data!C:C) -> 25 | C13: =_xlfn.XLOOKUP(A13, Raw_Data!A:A, Raw_Data!D:D) -> 3325 | D13: =_xlfn.XLOOKUP(A13, Archetype_Scores!A:A, Archetype_Scores!B:B) -> 0.63705 | E13: =_xlfn.XLOOKUP(A13, Archetype_Scores!A:A, Archetype_Scores!C:C) -> 0.50465 | F13: =_xlfn.XLOOKUP(A13, Archetype_Scores!A:A, Archetype_Scores!D:D) -> 0.3748 | G13: =_xlfn.XLOOKUP(A13, Archetype_Scores!A:A, Archetype_Scores!E:E) -> 0.4319
A14: =Archetype_Scores!A14 -> Diogo Jota | B14: =_xlfn.XLOOKUP(A14, Raw_Data!A:A, Raw_Data!C:C) -> 26 | C14: =_xlfn.XLOOKUP(A14, Raw_Data!A:A, Raw_Data!D:D) -> 1145 | D14: =_xlfn.XLOOKUP(A14, Archetype_Scores!A:A, Archetype_Scores!B:B) -> 0.63195 | E14: =_xlfn.XLOOKUP(A14, Archetype_Scores!A:A, Archetype_Scores!C:C) -> 0.54135 | F14: =_xlfn.XLOOKUP(A14, Archetype_Scores!A:A, Archetype_Scores!D:D) -> 0.69755 | G14: =_xlfn.XLOOKUP(A14, Archetype_Scores!A:A, Archetype_Scores!E:E) -> 0.5775
A15: =Archetype_Scores!A15 -> Gabriel Jesus | B15: =_xlfn.XLOOKUP(A15, Raw_Data!A:A, Raw_Data!C:C) -> 26 | C15: =_xlfn.XLOOKUP(A15, Raw_Data!A:A, Raw_Data!D:D) -> 1478 | D15: =_xlfn.XLOOKUP(A15, Archetype_Scores!A:A, Archetype_Scores!B:B) -> 0.6205 | E15: =_xlfn.XLOOKUP(A15, Archetype_Scores!A:A, Archetype_Scores!C:C) -> 0.688 | F15: =_xlfn.XLOOKUP(A15, Archetype_Scores!A:A, Archetype_Scores!D:D) -> 0.5641 | G15: =_xlfn.XLOOKUP(A15, Archetype_Scores!A:A, Archetype_Scores!E:E) -> 0.6254
A16: =Archetype_Scores!A16 -> Nicolas Jackson | B16: =_xlfn.XLOOKUP(A16, Raw_Data!A:A, Raw_Data!C:C) -> 22 | C16: =_xlfn.XLOOKUP(A16, Raw_Data!A:A, Raw_Data!D:D) -> 2799 | D16: =_xlfn.XLOOKUP(A16, Archetype_Scores!A:A, Archetype_Scores!B:B) -> 0.6047 | E16: =_xlfn.XLOOKUP(A16, Archetype_Scores!A:A, Archetype_Scores!C:C) -> 0.59025 | F16: =_xlfn.XLOOKUP(A16, Archetype_Scores!A:A, Archetype_Scores!D:D) -> 0.5161 | G16: =_xlfn.XLOOKUP(A16, Archetype_Scores!A:A, Archetype_Scores!E:E) -> 0.40235
A17: =Archetype_Scores!A17 -> Luis Díaz | B17: =_xlfn.XLOOKUP(A17, Raw_Data!A:A, Raw_Data!C:C) -> 26 | C17: =_xlfn.XLOOKUP(A17, Raw_Data!A:A, Raw_Data!D:D) -> 2629 | D17: =_xlfn.XLOOKUP(A17, Archetype_Scores!A:A, Archetype_Scores!B:B) -> 0.58915 | E17: =_xlfn.XLOOKUP(A17, Archetype_Scores!A:A, Archetype_Scores!C:C) -> 0.8902 | F17: =_xlfn.XLOOKUP(A17, Archetype_Scores!A:A, Archetype_Scores!D:D) -> 0.87475 | G17: =_xlfn.XLOOKUP(A17, Archetype_Scores!A:A, Archetype_Scores!E:E) -> 0.5997
A18: =Archetype_Scores!A18 -> Ollie Watkins | B18: =_xlfn.XLOOKUP(A18, Raw_Data!A:A, Raw_Data!C:C) -> 27 | C18: =_xlfn.XLOOKUP(A18, Raw_Data!A:A, Raw_Data!D:D) -> 3217 | D18: =_xlfn.XLOOKUP(A18, Archetype_Scores!A:A, Archetype_Scores!B:B) -> 0.5862 | E18: =_xlfn.XLOOKUP(A18, Archetype_Scores!A:A, Archetype_Scores!C:C) -> 0.59225 | F18: =_xlfn.XLOOKUP(A18, Archetype_Scores!A:A, Archetype_Scores!D:D) -> 0.4851 | G18: =_xlfn.XLOOKUP(A18, Archetype_Scores!A:A, Archetype_Scores!E:E) -> 0.38685
... A50: =Archetype_Scores!A50 -> Miguel Almirón | B50: =_xlfn.XLOOKUP(A50, Raw_Data!A:A, Raw_Data!C:C) -> 29 | C50: =_xlfn.XLOOKUP(A50, Raw_Data!A:A, Raw_Data!D:D) -> 1937 | D50: =_xlfn.XLOOKUP(A50, Archetype_Scores!A:A, Archetype_Scores!B:B) -> 0.1714 | E50: =_xlfn.XLOOKUP(A50, Archetype_Scores!A:A, Archetype_Scores!C:C) -> 0.5516 | F50: =_xlfn.XLOOKUP(A50, Archetype_Scores!A:A, Archetype_Scores!D:D) -> 0.5507 | G50: =_xlfn.XLOOKUP(A50, Archetype_Scores!A:A, Archetype_Scores!E:E) -> 0.57565
